Workbook

Sheet Dashboard
A1: LORE Labs -- CFO Dashboard
A2: ="Scenario: "&Scenarios!D3&" | all figures USD, live from model" -> Scenario: Base | all figures USD, live from model
B4: FY2026* | C4: FY2027 | D4: FY2028 | E4: FY2029 | F4: FY2030 | G4: FY2031
A5: Units shipped | B5: ='Pricing & Mix'!AG42 -> 0 | C5: ='Pricing & Mix'!AH42 -> 3697.5 | D5: ='Pricing & Mix'!AI42 -> 39252.5 | E5: ='Pricing & Mix'!AJ42 -> 120000 | F5: ='Pricing & Mix'!AK42 -> 250000 | G5: ='Pricing & Mix'!AL42 -> 400000
A6: Total revenue | B6: ='P&L'!AG16 -> 0 | C6: ='P&L'!AH16 -> 656496.72 | D6: ='P&L'!AI16 -> 10020674 | E6: ='P&L'!AJ16 -> 31635040 | F6: ='P&L'!AK16 -> 67070783 | G6: ='P&L'!AL16 -> 1.1133476e+08
A7: Hardware (net) | B7: ='P&L'!AG10 -> 0 | C7: ='P&L'!AH10 -> 605394.72 | D7: ='P&L'!AI10 -> 9016707.1 | E7: ='P&L'!AJ10 -> 26883763 | F7: ='P&L'!AK10 -> 54946080 | G7: ='P&L'!AL10 -> 87913728
A8: Subscriptions (Explorer + Trip Pass) | B8: ='P&L'!AG11+'P&L'!AG12 -> 0 | C8: ='P&L'!AH11+'P&L'!AH12 -> 0 | D8: ='P&L'!AI11+'P&L'!AI12 -> 362493.03 | E8: ='P&L'!AJ11+'P&L'!AJ12 -> 2296154.2 | F8: ='P&L'!AK11+'P&L'!AK12 -> 6214231.9 | G8: ='P&L'!AL11+'P&L'!AL12 -> 12347008
A9: Accessories | B9: ='P&L'!AG13 -> 0 | C9: ='P&L'!AH13 -> 49916.25 | D9: ='P&L'!AI13 -> 529908.75 | E9: ='P&L'!AJ13 -> 1620000 | F9: ='P&L'!AK13 -> 3375000 | G9: ='P&L'!AL13 -> 5400000
A10: Affiliate | B10: ='P&L'!AG14 -> 0 | C10: ='P&L'!AH14 -> 1185.75 | D10: ='P&L'!AI14 -> 62065.291 | E10: ='P&L'!AJ14 -> 425922.73 | F10: ='P&L'!AK14 -> 1413471 | G10: ='P&L'!AL14 -> 3430021.2
A11: B2B fleet | B11: ='P&L'!AG15 -> 0 | C11: ='P&L'!AH15 -> 0 | D11: ='P&L'!AI15 -> 49500 | E11: ='P&L'!AJ15 -> 409200 | F11: ='P&L'!AK15 -> 1122000 | G11: ='P&L'!AL15 -> 2244000
A12: Revenue growth YoY | B12: =0 -> 0 | C12: =IF(B6>0,C6/B6-1,0) -> 0 | D12: =IF(C6>0,D6/C6-1,0) -> 14.26386 | E12: =IF(D6>0,E6/D6-1,0) -> 2.1569772 | F12: =IF(E6>0,F6/E6-1,0) -> 1.1201422 | G12: =IF(F6>0,G6/F6-1,0) -> 0.65995911
A13: Gross profit | B13: ='P&L'!AG23 -> 0 | C13: ='P&L'!AH23 -> 73619.895 | D13: ='P&L'!AI23 -> 2390437.7 | E13: ='P&L'!AJ23 -> 9564896.9 | F13: ='P&L'!AK23 -> 24062948 | G13: ='P&L'!AL23 -> 44237881
A14: Gross margin % | B14: ='P&L'!AG24 -> 0 | C14: ='P&L'!AH24 -> 0.11214054 | D14: ='P&L'!AI24 -> 0.23855058 | E14: ='P&L'!AJ24 -> 0.30235134 | F14: ='P&L'!AK24 -> 0.35876946 | G14: ='P&L'!AL24 -> 0.39734116
A15: Hardware gross margin % | B15: ='P&L'!AG44 -> 0 | C15: ='P&L'!AH44 -> 0.087054829 | D15: ='P&L'!AI44 -> 0.21290764 | E15: ='P&L'!AJ44 -> 0.25284801 | F15: ='P&L'!AK44 -> 0.29527017 | G15: ='P&L'!AL44 -> 0.31801954
A16: EBITDA | B16: ='P&L'!AG32 -> -198666.67 | C16: ='P&L'!AH32 -> -4115400 | D16: ='P&L'!AI32 -> -4613729.6 | E16: ='P&L'!AJ32 -> -8160796.7 | F16: ='P&L'!AK32 -> -6583183.9 | G16: ='P&L'!AL32 -> -621008.36
A17: EBITDA margin % | B17: ='P&L'!AG33 -> 0 | C17: ='P&L'!AH33 -> -6.268729 | D17: ='P&L'!AI33 -> -0.46042108 | E17: ='P&L'!AJ33 -> -0.25796701 | F17: ='P&L'!AK33 -> -0.098152781 | G17: ='P&L'!AL33 -> -0.0055778481
A18: Net income | B18: ='P&L'!AG40 -> -194513.33 | C18: ='P&L'!AH40 -> -4102395.5 | D18: ='P&L'!AI40 -> -4569902 | E18: ='P&L'!AJ40 -> -7748020.6 | F18: ='P&L'!AK40 -> -6678268.7 | G18: ='P&L'!AL40 -> -192459.67
A19: Ending cash | B19: ='Cash Flow'!AG28 -> 1305486.7 | C19: ='Cash Flow'!AH28 -> 2556526.4 | D19: ='Cash Flow'!AI28 -> 23250149 | E19: ='Cash Flow'!AJ28 -> 14378505 | F19: ='Cash Flow'!AK28 -> 38382308 | G19: ='Cash Flow'!AL28 -> 33426498
A20: Net burn (op + inv cash flow) | B20: ='Cash Flow'!AG29 -> 194513.33 | C20: ='Cash Flow'!AH29 -> 4748960.3 | D20: ='Cash Flow'!AI29 -> 7306377.5 | E20: ='Cash Flow'!AJ29 -> 8871643.7 | F20: ='Cash Flow'!AK29 -> 10996197 | G20: ='Cash Flow'!AL29 -> 4955810.2
A21: Equity raised in year | B21: ='Cash Flow'!AG22 -> 1500000 | C21: ='Cash Flow'!AH22 -> 6000000 | D21: ='Cash Flow'!AI22 -> 28000000 | E21: ='Cash Flow'!AJ22 -> 0 | F21: ='Cash Flow'!AK22 -> 35000000 | G21: ='Cash Flow'!AL22 -> 0
A22: Paid subscribers (end) | B22: ='Subscription Cohorts'!AG19 -> 0 | C22: ='Subscription Cohorts'!AH19 -> 0 | D22: ='Subscription Cohorts'!AI19 -> 7626.4187 | E22: ='Subscription Cohorts'!AJ19 -> 32142.086 | F22: ='Subscription Cohorts'!AK19 -> 73636.421 | G22: ='Subscription Cohorts'!AL19 -> 132277.32
A23: Subscription ARR (end) | B23: ='Subscription Cohorts'!AG24 -> 0 | C23: ='Subscription Cohorts'!AH24 -> 0 | D23: ='Subscription Cohorts'!AI24 -> 786259.36 | E23: ='Subscription Cohorts'!AJ24 -> 3313746.3 | F23: ='Subscription Cohorts'!AK24 -> 7591679.4 | G23: ='Subscription Cohorts'!AL24 -> 13637368
A24: Active devices (end) | B24: ='Subscription Cohorts'!AG29 -> 0 | C24: ='Subscription Cohorts'!AH29 -> 3655 | D24: ='Subscription Cohorts'!AI29 -> 39124.509 | E24: ='Subscription Cohorts'!AJ29 -> 138343.29 | F24: ='Subscription Cohorts'!AK29 -> 332813.71 | G24: ='Subscription Cohorts'!AL29 -> 619969.94
A25: Headcount (end) | B25: ='Headcount Plan'!AG104 -> 3 | C25: ='Headcount Plan'!AH104 -> 14 | D25: ='Headcount Plan'!AI104 -> 30 | E25: ='Headcount Plan'!AJ104 -> 61 | F25: ='Headcount Plan'!AK104 -> 92 | G25: ='Headcount Plan'!AL104 -> 121
A26: * FY2026 = Nov-Dec stub
A28: Funding & runway
A29: Total equity raised through FY2031 | B29: ='Funding & Runway'!D12 -> 70500000
A30: Minimum month-end cash, Nov-26..Dec-28 | B30: ='Funding & Runway'!D13 -> 420194.5
A31: Month of minimum cash | B31: ='Funding & Runway'!D14 -> May-27
A32: Peak monthly net burn (monthly periods) | B32: ='Funding & Runway'!D16 -> 1160489.6
A33: Month of peak burn | B33: ='Funding & Runway'!D17 -> Oct-27
A34: Peak average monthly burn (any period incl. FY29-31) | B34: ='Funding & Runway'!D18 -> 1160489.6
A35: First monthly period with positive EBITDA (monthly cols) | B35: ='Funding & Runway'!D20 -> after Dec-28
A36: First fiscal year with positive EBITDA | B36: ='Funding & Runway'!D21 -> after FY31
A37: First fiscal year with positive operating+investing cash flow | B37: ='Funding & Runway'!D22 -> after FY31
A38: Minimum period-end cash incl. FY29-31 | B38: ='Funding & Runway'!D15 -> 420194.5

Sheet Assumptions
A1: Assumptions -- all inputs in BLUE. Estimates unless a source is cited. Prices ex-VAT/sales tax.
B2: Model base year | C2: 2027
A3: Input | B3: Name | C3: Value | D3: Unit | E3: Basis / source
A5: General & finance
A6: Opening cash (Nov-2026, before pre-seed) | B6: opening_cash | C6: 0 | D6: $ | E6: Founder-funded work to date excluded.
A7: Interest earned on cash (annual) | B7: interest_rate | C7: 0.035 | D7: %/yr | E7: US T-bill / treasury MMF yields ~3.5-4% (2026), conservative.
A8: Corporate income tax rate (after NOLs) | B8: tax_rate | C8: 0.21 | D8: % | E8: US federal 21%; state ignored; NOLs offset until cumulative pre-tax > 0.
A9: Employer burden on salary (benefits, payroll tax) | B9: burden | C9: 0.25 | D9: % | E9: Typical US startup 20-30%. Legal-ops owns final salary bands.
A10: Annual salary inflation (from 2028) | B10: salary_infl | C10: 0.03 | D10: %/yr | E10: Estimate.
A12: Hardware pricing (MSRP from COMPANY.md; KS prices = early-bird)
A13: LORE Pebble MSRP | B13: msrp_peb | C13: 149 | D13: $ | E13: COMPANY.md target price.
A14: LORE Square MSRP | B14: msrp_sq | C14: 299 | D14: $ | E14: Research final (holds COMPANY.md). CFO FLAG: with hardware/bom landed $227 @10k the DTC hardware margin is single-digit until DRAM normalises & 100k-tier pricing; see pricing-margin-sensitivity.md.
A15: LORE Atlas MSRP | B15: msrp_atl | C15: 599 | D15: $ | E15: Research recommends $599 (COMPANY.md $549). Atlas launches Sep-2028 (CFO assumption: NTN + camera + titanium need a separate EVT/DVT cycle).
A16: Kickstarter blended pledge price -- Pebble | B16: ks_peb | C16: 112 | D16: $ | E16: Research tiers $99 / $115 / $129, weighted ~25/45/30.
A17: Kickstarter blended pledge price -- Square | B17: ks_sq | C17: 226 | D17: $ | E17: Research tiers $199 / $229 / $259, weighted ~25/45/30.
A18: Post-campaign pre-order price -- Pebble | B18: pre_peb | C18: 129 | D18: $ | E18: BackerKit/website pre-order, ~13% off (Research).
A19: Kickstarter blended pledge price -- Atlas | B19: ks_atl | C19: 442 | D19: $ | E19: Research tiers $399 / $449 / $499.
A20: Post-campaign pre-order price -- Atlas | B20: pre_atl | C20: 499 | D20: $ | E20: Research KS standard tier.
A21: Post-campaign pre-order price -- Square | B21: pre_sq | C21: 259 | D21: $ | E21: ~13% off $299 (Research).
A22: Average DTC promo discount vs MSRP | B22: dtc_disc | C22: 0.06 | D22: % | E22: Blended codes/bundles/Black Friday.
A23: Retailer / distributor margin (off MSRP) | B23: retail_margin | C23: 0.38 | D23: % | E23: Consumer electronics retail margins typically 30-45% incl. distributor; estimate.
A24: Returns & refunds allowance (of HW revenue) | B24: returns_pct | C24: 0.04 | D24: % | E24: Consumer electronics 3-8%; estimate.
A26: Landed COGS per unit, 10k tier (RECONCILED to hardware/bom/cogs_summary.csv, 30-Oct-2026); NRE (cert/tooling) is expensed/capitalised separately
A27: Pebble (ships as Pebble Lite ECR spec) -- FOB incl. conversion & yield | B27: bom_peb | C27: 62.03 | D27: $ | E27: hardware/bom: Pebble Lite (ECR, cloud AI, no DRAM) FOB @10k $62.03. Full-spec Pebble (on-device 1B model) is $125.06 FOB -> negative margin at $149, so CFO base case ships the ECR spec.
A28: Pebble -- royalties | B28: asm_peb | C28: 0 | D28: $ | E28: hardware/bom: none (no cellular).
A29: Pebble -- extra packaging (included in FOB) | B29: pkg_peb | C29: 0 | D29: $ | E29: Included in hardware/bom FOB.
A30: Square -- FOB incl. conversion & yield | B30: bom_sq | C30: 219.11 | D30: $ | E30: hardware/bom @10k (DRAM priced at 2026-27 shortage levels; normalised DRAM saves ~$20).
A31: Square -- cellular SEP royalties | B31: asm_sq | C31: 5.8 | D31: $ | E31: hardware/bom estimate.
A32: Square -- extra packaging (included in FOB) | B32: pkg_sq | C32: 0 | D32: $
A33: Atlas -- FOB incl. conversion & yield | B33: bom_atl | C33: 305.55 | D33: $ | E33: hardware/bom @10k.
A34: Atlas -- royalties | B34: asm_atl | C34: 8.7 | D34: $ | E34: hardware/bom estimate.
A35: Atlas -- extra packaging (included in FOB) | B35: pkg_atl | C35: 0 | D35: $
A36: Inbound freight, insurance & duties (% of FOB) | B36: freight_duty | C36: 0.01 | D36: % | E36: hardware/bom: freight $1.3-2.2/unit; 0% US duty assumes VN/MY FATP (China FATP adds ~20% of FOB -- see sensitivity).
A37: Warranty reserve (% of HW revenue) | B37: warranty_pct | C37: 0.02 | D37: % | E37: 1-2 yr warranty; estimate.
A38: DTC outbound shipping + 3PL pick/pack per unit | B38: dtc_ship | C38: 11 | D38: $ | E38: 3PL ~$3-4 + ground/intl blend.
A39: Retail distribution cost per unit | B39: retail_dist | C39: 4 | D39: $ | E39: Palletised to DC.
A40: Pre-order (KS) fulfilment cost per unit, net of shipping charged | B40: ks_fulfil_net | C40: 6 | D40: $ | E40: Backers pay shipping; residual subsidy + 3PL.
A41: Card processing -- % (DTC) | B41: pay_pct | C41: 0.029 | D41: % | E41: Stripe/Shopify Payments standard 2.9% + $0.30.
A42: Card processing -- fixed per order | B42: pay_fixed | C42: 0.3 | D42: $
A44: Kickstarter / pre-orders (Q2-2027 campaign; ships Nov-2027 to Jan-2028)
...

Sheet Scenarios
A1: Scenarios -- set the selector (1 = Bear, 2 = Base, 3 = Bull). Every sheet recalculates.
A3: ACTIVE SCENARIO (1/2/3) | C3: 2 | D3: =CHOOSE(Scenario,"Bear","Base","Bull") -> Base
A5: Driver | B5: Name | C5: Bear | D5: Base | E5: Bull | F5: LIVE | G5: What it does / rationale
A6: Unit volume multiplier (KS + regular sales) | B6: sc_vol | C6: 0.55 | D6: 1 | E6: 1.45 | F6: =CHOOSE(Scenario,C6,D6,E6) -> 1 | G6: Bear ~ a mid-sized KS ($0.55M) and slow retail; bull ~ breakout KS + strong retail sell-through.
A7: Hardware & subscription price multiplier | B7: sc_price | C7: 0.93 | D7: 1 | E7: 1 | F7: =CHOOSE(Scenario,C7,D7,E7) -> 1 | G7: Bear assumes ~7% deeper promotions / price cuts.
A8: Subscription attach multiplier | B8: sc_attach | C8: 0.7 | D8: 1 | E8: 1.25 | F8: =CHOOSE(Scenario,C8,D8,E8) -> 1 | G8: Applied to post-trial paid conversion per SKU.
A9: Subscription churn multiplier | B9: sc_churn | C9: 1.3 | D9: 1 | E9: 0.8 | F9: =CHOOSE(Scenario,C9,D9,E9) -> 1 | G9: Bear 7.8%/mo, base 6.0%/mo, bull 4.8%/mo.
A10: Landed COGS multiplier | B10: sc_cogs | C10: 1.1 | D10: 1 | E10: 0.95 | F10: =CHOOSE(Scenario,C10,D10,E10) -> 1 | G10: Bear: memory price spike / tariffs; bull: better ODM quote.
A11: CAC / paid-acquisition multiplier | B11: sc_cac | C11: 1.35 | D11: 1 | E11: 0.85 | F11: =CHOOSE(Scenario,C11,D11,E11) -> 1 | G11: Applied to paid CAC per DTC unit.
A15: SCENARIO SNAPSHOT (static values written by scripts/run_all.py after LibreOffice recalc of each scenario; re-run the script after changing inputs)
A16: Metric | B16: Scenario | C16: FY2026 | D16: FY2027 | E16: FY2028 | F16: FY2029 | G16: FY2030 | H16: FY2031
A17: Units shipped | B17: Bear | C17: 0 | D17: 2033.625 | E17: 21588.875 | F17: 66000 | G17: 137500 | H17: 220000
A18: Units shipped | B18: Base | C18: 0 | D18: 3697.5 | E18: 39252.5 | F18: 120000 | G18: 250000 | H18: 400000
A19: Units shipped | B19: Bull | C19: 0 | D19: 5361.375 | E19: 56916.125 | F19: 174000 | G19: 362500 | H19: 580000
A20: Revenue | B20: Bear | C20: 0 | D20: 335843.72 | E20: 5099835.3 | F20: 16034941 | G20: 33901014 | H20: 56150489
A21: Revenue | B21: Base | C21: 0 | D21: 656496.72 | E21: 10020674 | F21: 31635040 | G21: 67070783 | H21: 1.1133476e+08
A22: Revenue | B22: Bull | C22: 0 | D22: 951920.24 | E22: 14637557 | F22: 46643891 | G22: 99502275 | H22: 1.6612553e+08
A23: Gross margin % | B23: Bear | C23: 0 | D23: -0.035751427 | E23: 0.11661911 | F23: 0.1916271 | G23: 0.25713058 | H23: 0.30179441
A24: Gross margin % | B24: Base | C24: 0 | D24: 0.11214054 | E24: 0.23855058 | F24: 0.30235134 | G24: 0.35876946 | H24: 0.39734116
A25: Gross margin % | B25: Bull | C25: 0 | D25: 0.15158436 | E25: 0.27288933 | F25: 0.33654443 | G25: 0.39209644 | H25: 0.4305719
A26: EBITDA | B26: Bear | C26: -198666.67 | D26: -4159019.2 | E26: -5904312.4 | F26: -13066128 | G26: -18895179 | H26: -23192540
A27: EBITDA | B27: Base | C27: -198666.67 | D27: -4115400 | E27: -4613729.6 | F27: -8160796.7 | G27: -6583183.9 | H27: -621008.36
A28: EBITDA | B28: Bull | C28: -198666.67 | D28: -4083451.4 | E28: -3466513.7 | F28: -3464032 | G28: 5620914.4 | H28: 22395093
... A34: Subscription ARR (end) | B34: Bull | C34: 0 | D34: 0 | E34: 1492299.1 | F34: 6492515 | G34: 15190172 | H34: 27738297
A35: Min cash (with planned rounds) / peak cumulative burn / first EBITDA+ FY | B35: Bear | C35: -3617882.7 | D35: 74117883 | E35: after FY31
A36: Min cash (with planned rounds) / peak cumulative burn / first EBITDA+ FY | B36: Base | C36: 420194.5 | D36: 37073502 | E36: after FY31
A37: Min cash (with planned rounds) / peak cumulative burn / first EBITDA+ FY | B37: Bull | C37: 420194.5 | D37: 16791529 | E37: 2030

Sheet Pricing & Mix
A1: Pricing & SKU mix -- units by SKU and channel
A2: Period | C2: =Timeline!C2 -> Nov-26 | D2: =Timeline!D2 -> Dec-26 | E2: =Timeline!E2 -> Jan-27 | F2: =Timeline!F2 -> Feb-27 | G2: =Timeline!G2 -> Mar-27 | H2: =Timeline!H2 -> Apr-27 | I2: =Timeline!I2 -> May-27 | J2: =Timeline!J2 -> Jun-27 | ... AE2: =Timeline!AE2 -> FY2031 | AG2: FY2026 (Nov-Dec) | AH2: FY2027 | AI2: FY2028 | AJ2: FY2029 | AK2: FY2030 | AL2: FY2031
A3: Year | C3: =Timeline!C3 -> 2026 | D3: =Timeline!D3 -> 2026 | E3: =Timeline!E3 -> 2027 | F3: =Timeline!F3 -> 2027 | G3: =Timeline!G3 -> 2027 | H3: =Timeline!H3 -> 2027 | I3: =Timeline!I3 -> 2027 | J3: =Timeline!J3 -> 2027 | ... AE3: =Timeline!AE3 -> 2031 | AG3: 2026 | AH3: 2027 | AI3: 2028 | AJ3: 2029 | AK3: 2030 | AL3: 2031
A4: Months in period | C4: =Timeline!C4 -> 1 | D4: =Timeline!D4 -> 1 | E4: =Timeline!E4 -> 1 | F4: =Timeline!F4 -> 1 | G4: =Timeline!G4 -> 1 | H4: =Timeline!H4 -> 1 | I4: =Timeline!I4 -> 1 | J4: =Timeline!J4 -> 1 | ... AE4: =Timeline!AE4 -> 12
A5: Period start | C5: =Timeline!C5 -> 46327 | D5: =Timeline!D5 -> 46357 | E5: =Timeline!E5 -> 46388 | F5: =Timeline!F5 -> 46419 | G5: =Timeline!G5 -> 46447 | H5: =Timeline!H5 -> 46478 | I5: =Timeline!I5 -> 46508 | J5: =Timeline!J5 -> 46539 | ... AE5: =Timeline!AE5 -> 47849
A6: Period key | C6: =Timeline!C6 -> 202611 | D6: =Timeline!D6 -> 202612 | E6: =Timeline!E6 -> 202701 | F6: =Timeline!F6 -> 202702 | G6: =Timeline!G6 -> 202703 | H6: =Timeline!H6 -> 202704 | I6: =Timeline!I6 -> 202705 | J6: =Timeline!J6 -> 202706 | ... AE6: =Timeline!AE6 -> 2031
A9: Prices ($/unit)
A10: MSRP -- Pebble | B10: $ | C10: =msrp_peb*sc_price -> 149 | D10: =msrp_peb*sc_price -> 149 | E10: =msrp_peb*sc_price -> 149 | F10: =msrp_peb*sc_price -> 149 | G10: =msrp_peb*sc_price -> 149 | H10: =msrp_peb*sc_price -> 149 | I10: =msrp_peb*sc_price -> 149 | J10: =msrp_peb*sc_price -> 149 | ... AE10: =msrp_peb*sc_price -> 149
A11: MSRP -- Square | B11: $ | C11: =msrp_sq*sc_price -> 299 | D11: =msrp_sq*sc_price -> 299 | E11: =msrp_sq*sc_price -> 299 | F11: =msrp_sq*sc_price -> 299 | G11: =msrp_sq*sc_price -> 299 | H11: =msrp_sq*sc_price -> 299 | I11: =msrp_sq*sc_price -> 299 | J11: =msrp_sq*sc_price -> 299 | ... AE11: =msrp_sq*sc_price -> 299
A12: MSRP -- Atlas | B12: $ | C12: =msrp_atl*sc_price -> 599 | D12: =msrp_atl*sc_price -> 599 | E12: =msrp_atl*sc_price -> 599 | F12: =msrp_atl*sc_price -> 599 | G12: =msrp_atl*sc_price -> 599 | H12: =msrp_atl*sc_price -> 599 | I12: =msrp_atl*sc_price -> 599 | J12: =msrp_atl*sc_price -> 599 | ... AE12: =msrp_atl*sc_price -> 599
A13: DTC net price -- Pebble | B13: $ | C13: ='Pricing & Mix'!C10*(1-dtc_disc) -> 140.06 | D13: ='Pricing & Mix'!D10*(1-dtc_disc) -> 140.06 | E13: ='Pricing & Mix'!E10*(1-dtc_disc) -> 140.06 | F13: ='Pricing & Mix'!F10*(1-dtc_disc) -> 140.06 | G13: ='Pricing & Mix'!G10*(1-dtc_disc) -> 140.06 | H13: ='Pricing & Mix'!H10*(1-dtc_disc) -> 140.06 | I13: ='Pricing & Mix'!I10*(1-dtc_disc) -> 140.06 | J13: ='Pricing & Mix'!J10*(1-dtc_disc) -> 140.06 | ... AE13: ='Pricing & Mix'!AE10*(1-dtc_disc) -> 140.06
A14: DTC net price -- Square | B14: $ | C14: ='Pricing & Mix'!C11*(1-dtc_disc) -> 281.06 | D14: ='Pricing & Mix'!D11*(1-dtc_disc) -> 281.06 | E14: ='Pricing & Mix'!E11*(1-dtc_disc) -> 281.06 | F14: ='Pricing & Mix'!F11*(1-dtc_disc) -> 281.06 | G14: ='Pricing & Mix'!G11*(1-dtc_disc) -> 281.06 | H14: ='Pricing & Mix'!H11*(1-dtc_disc) -> 281.06 | I14: ='Pricing & Mix'!I11*(1-dtc_disc) -> 281.06 | J14: ='Pricing & Mix'!J11*(1-dtc_disc) -> 281.06 | ... AE14: ='Pricing & Mix'!AE11*(1-dtc_disc) -> 281.06
A15: DTC net price -- Atlas | B15: $ | C15: ='Pricing & Mix'!C12*(1-dtc_disc) -> 563.06 | D15: ='Pricing & Mix'!D12*(1-dtc_disc) -> 563.06 | E15: ='Pricing & Mix'!E12*(1-dtc_disc) -> 563.06 | F15: ='Pricing & Mix'!F12*(1-dtc_disc) -> 563.06 | G15: ='Pricing & Mix'!G12*(1-dtc_disc) -> 563.06 | H15: ='Pricing & Mix'!H12*(1-dtc_disc) -> 563.06 | I15: ='Pricing & Mix'!I12*(1-dtc_disc) -> 563.06 | J15: ='Pricing & Mix'!J12*(1-dtc_disc) -> 563.06 | ... AE15: ='Pricing & Mix'!AE12*(1-dtc_disc) -> 563.06
A16: Retail sell-in price -- Pebble | B16: $ | C16: ='Pricing & Mix'!C10*(1-retail_margin) -> 92.38 | D16: ='Pricing & Mix'!D10*(1-retail_margin) -> 92.38 | E16: ='Pricing & Mix'!E10*(1-retail_margin) -> 92.38 | F16: ='Pricing & Mix'!F10*(1-retail_margin) -> 92.38 | G16: ='Pricing & Mix'!G10*(1-retail_margin) -> 92.38 | H16: ='Pricing & Mix'!H10*(1-retail_margin) -> 92.38 | I16: ='Pricing & Mix'!I10*(1-retail_margin) -> 92.38 | J16: ='Pricing & Mix'!J10*(1-retail_margin) -> 92.38 | ... AE16: ='Pricing & Mix'!AE10*(1-retail_margin) -> 92.38
A17: Retail sell-in price -- Square | B17: $ | C17: ='Pricing & Mix'!C11*(1-retail_margin) -> 185.38 | D17: ='Pricing & Mix'!D11*(1-retail_margin) -> 185.38 | E17: ='Pricing & Mix'!E11*(1-retail_margin) -> 185.38 | F17: ='Pricing & Mix'!F11*(1-retail_margin) -> 185.38 | G17: ='Pricing & Mix'!G11*(1-retail_margin) -> 185.38 | H17: ='Pricing & Mix'!H11*(1-retail_margin) -> 185.38 | I17: ='Pricing & Mix'!I11*(1-retail_margin) -> 185.38 | J17: ='Pricing & Mix'!J11*(1-retail_margin) -> 185.38 | ... AE17: ='Pricing & Mix'!AE11*(1-retail_margin) -> 185.38
A18: Retail sell-in price -- Atlas | B18: $ | C18: ='Pricing & Mix'!C12*(1-retail_margin) -> 371.38 | D18: ='Pricing & Mix'!D12*(1-retail_margin) -> 371.38 | E18: ='Pricing & Mix'!E12*(1-retail_margin) -> 371.38 | F18: ='Pricing & Mix'!F12*(1-retail_margin) -> 371.38 | G18: ='Pricing & Mix'!G12*(1-retail_margin) -> 371.38 | H18: ='Pricing & Mix'!H12*(1-retail_margin) -> 371.38 | I18: ='Pricing & Mix'!I12*(1-retail_margin) -> 371.38 | J18: ='Pricing & Mix'!J12*(1-retail_margin) -> 371.38 | ... AE18: ='Pricing & Mix'!AE12*(1-retail_margin) -> 371.38
A19: Pre-order blended price -- Pebble | B19: $ | C19: =(ks_units*ks_peb+pre_units*pre_peb)/(ks_units+pre_units)*sc_price -> 115.4 | D19: =(ks_units*ks_peb+pre_units*pre_peb)/(ks_units+pre_units)*sc_price -> 115.4 | E19: =(ks_units*ks_peb+pre_units*pre_peb)/(ks_units+pre_units)*sc_price -> 115.4 | F19: =(ks_units*ks_peb+pre_units*pre_peb)/(ks_units+pre_units)*sc_price -> 115.4 | G19: =(ks_units*ks_peb+pre_units*pre_peb)/(ks_units+pre_units)*sc_price -> 115.4 | H19: =(ks_units*ks_peb+pre_units*pre_peb)/(ks_units+pre_units)*sc_price -> 115.4 | I19: =(ks_units*ks_peb+pre_units*pre_peb)/(ks_units+pre_units)*sc_price -> 115.4 | J19: =(ks_units*ks_peb+pre_units*pre_peb)/(ks_units+pre_units)*sc_price -> 115.4 | ... AE19: =(ks_units*ks_peb+pre_units*pre_peb)/(ks_units+pre_units)*sc_price -> 115.4
A20: Pre-order blended price -- Square | B20: $ | C20: =(ks_units*ks_sq+pre_units*pre_sq)/(ks_units+pre_units)*sc_price -> 232.6 | D20: =(ks_units*ks_sq+pre_units*pre_sq)/(ks_units+pre_units)*sc_price -> 232.6 | E20: =(ks_units*ks_sq+pre_units*pre_sq)/(ks_units+pre_units)*sc_price -> 232.6 | F20: =(ks_units*ks_sq+pre_units*pre_sq)/(ks_units+pre_units)*sc_price -> 232.6 | G20: =(ks_units*ks_sq+pre_units*pre_sq)/(ks_units+pre_units)*sc_price -> 232.6 | H20: =(ks_units*ks_sq+pre_units*pre_sq)/(ks_units+pre_units)*sc_price -> 232.6 | I20: =(ks_units*ks_sq+pre_units*pre_sq)/(ks_units+pre_units)*sc_price -> 232.6 | J20: =(ks_units*ks_sq+pre_units*pre_sq)/(ks_units+pre_units)*sc_price -> 232.6 | ... AE20: =(ks_units*ks_sq+pre_units*pre_sq)/(ks_units+pre_units)*sc_price -> 232.6
A21: Pre-order blended price -- Atlas | B21: $ | C21: =(ks_units*ks_atl+pre_units*pre_atl)/(ks_units+pre_units)*sc_price -> 453.4 | D21: =(ks_units*ks_atl+pre_units*pre_atl)/(ks_units+pre_units)*sc_price -> 453.4 | E21: =(ks_units*ks_atl+pre_units*pre_atl)/(ks_units+pre_units)*sc_price -> 453.4 | F21: =(ks_units*ks_atl+pre_units*pre_atl)/(ks_units+pre_units)*sc_price -> 453.4 | G21: =(ks_units*ks_atl+pre_units*pre_atl)/(ks_units+pre_units)*sc_price -> 453.4 | H21: =(ks_units*ks_atl+pre_units*pre_atl)/(ks_units+pre_units)*sc_price -> 453.4 | I21: =(ks_units*ks_atl+pre_units*pre_atl)/(ks_units+pre_units)*sc_price -> 453.4 | J21: =(ks_units*ks_atl+pre_units*pre_atl)/(ks_units+pre_units)*sc_price -> 453.4 | ... AE21: =(ks_units*ks_atl+pre_units*pre_atl)/(ks_units+pre_units)*sc_price -> 453.4
A23: Units
A24: Regular units sold (after scenario) | B24: units | C24: =Assumptions!C102*sc_vol -> 0 | D24: =Assumptions!D102*sc_vol -> 0 | E24: =Assumptions!E102*sc_vol -> 0 | F24: =Assumptions!F102*sc_vol -> 0 | G24: =Assumptions!G102*sc_vol -> 0 | H24: =Assumptions!H102*sc_vol -> 0 | I24: =Assumptions!I102*sc_vol -> 0 | J24: =Assumptions!J102*sc_vol -> 0 | ... AE24: =Assumptions!AE102*sc_vol -> 400000 | AG24: =SUMIF($C$3:$AE$3,AG$3,$C24:$AE24) -> 0 | AH24: =SUMIF($C$3:$AE$3,AH$3,$C24:$AE24) -> 0 | AI24: =SUMIF($C$3:$AE$3,AI$3,$C24:$AE24) -> 37950 | AJ24: =SUMIF($C$3:$AE$3,AJ$3,$C24:$AE24) -> 120000 | AK24: =SUMIF($C$3:$AE$3,AK$3,$C24:$AE24) -> 250000 | AL24: =SUMIF($C$3:$AE$3,AL$3,$C24:$AE24) -> 400000
A25: Mix -- Pebble | B25: % | C25: =Assumptions!C107 -> 0.53 | D25: =Assumptions!D107 -> 0.53 | E25: =Assumptions!E107 -> 0.53 | F25: =Assumptions!F107 -> 0.53 | G25: =Assumptions!G107 -> 0.53 | H25: =Assumptions!H107 -> 0.53 | I25: =Assumptions!I107 -> 0.53 | J25: =Assumptions!J107 -> 0.53 | ... AE25: =Assumptions!AE107 -> 0.45
A26: Mix -- Square | B26: % | C26: =Assumptions!C108 -> 0.47 | D26: =Assumptions!D108 -> 0.47 | E26: =Assumptions!E108 -> 0.47 | F26: =Assumptions!F108 -> 0.47 | G26: =Assumptions!G108 -> 0.47 | H26: =Assumptions!H108 -> 0.47 | I26: =Assumptions!I108 -> 0.47 | J26: =Assumptions!J108 -> 0.47 | ... AE26: =Assumptions!AE108 -> 0.4
A27: Mix -- Atlas | B27: % | C27: =Assumptions!C109 -> 0 | D27: =Assumptions!D109 -> 0 | E27: =Assumptions!E109 -> 0 | F27: =Assumptions!F109 -> 0 | G27: =Assumptions!G109 -> 0 | H27: =Assumptions!H109 -> 0 | I27: =Assumptions!I109 -> 0 | J27: =Assumptions!J109 -> 0 | ... AE27: =Assumptions!AE109 -> 0.15
A28: Retail share | B28: % | C28: =Assumptions!C106 -> 0 | D28: =Assumptions!D106 -> 0 | E28: =Assumptions!E106 -> 0 | F28: =Assumptions!F106 -> 0 | G28: =Assumptions!G106 -> 0 | H28: =Assumptions!H106 -> 0 | I28: =Assumptions!I106 -> 0 | J28: =Assumptions!J106 -> 0 | ... AE28: =Assumptions!AE106 -> 0.35
A29: DTC units -- Pebble | B29: units | C29: ='Pricing & Mix'!C24*'Pricing & Mix'!C25*(1-'Pricing & Mix'!C28) -> 0 | D29: ='Pricing & Mix'!D24*'Pricing & Mix'!D25*(1-'Pricing & Mix'!D28) -> 0 | E29: ='Pricing & Mix'!E24*'Pricing & Mix'!E25*(1-'Pricing & Mix'!E28) -> 0 | F29: ='Pricing & Mix'!F24*'Pricing & Mix'!F25*(1-'Pricing & Mix'!F28) -> 0 | G29: ='Pricing & Mix'!G24*'Pricing & Mix'!G25*(1-'Pricing & Mix'!G28) -> 0 | H29: ='Pricing & Mix'!H24*'Pricing & Mix'!H25*(1-'Pricing & Mix'!H28) -> 0 | I29: ='Pricing & Mix'!I24*'Pricing & Mix'!I25*(1-'Pricing & Mix'!I28) -> 0 | J29: ='Pricing & Mix'!J24*'Pricing & Mix'!J25*(1-'Pricing & Mix'!J28) -> 0 | ... AE29: ='Pricing & Mix'!AE24*'Pricing & Mix'!AE25*(1-'Pricing & Mix'!AE28) -> 117000 | AG29: =SUMIF($C$3:$AE$3,AG$3,$C29:$AE29) -> 0 | AH29: =SUMIF($C$3:$AE$3,AH$3,$C29:$AE29) -> 0 | AI29: =SUMIF($C$3:$AE$3,AI$3,$C29:$AE29) -> 13897.125 | AJ29: =SUMIF($C$3:$AE$3,AJ$3,$C29:$AE29) -> 37800 | AK29: =SUMIF($C$3:$AE$3,AK$3,$C29:$AE29) -> 73125 | AL29: =SUMIF($C$3:$AE$3,AL$3,$C29:$AE29) -> 117000
A30: DTC units -- Square | B30: units | C30: ='Pricing & Mix'!C24*'Pricing & Mix'!C26*(1-'Pricing & Mix'!C28) -> 0 | D30: ='Pricing & Mix'!D24*'Pricing & Mix'!D26*(1-'Pricing & Mix'!D28) -> 0 | E30: ='Pricing & Mix'!E24*'Pricing & Mix'!E26*(1-'Pricing & Mix'!E28) -> 0 | F30: ='Pricing & Mix'!F24*'Pricing & Mix'!F26*(1-'Pricing & Mix'!F28) -> 0 | G30: ='Pricing & Mix'!G24*'Pricing & Mix'!G26*(1-'Pricing & Mix'!G28) -> 0 | H30: ='Pricing & Mix'!H24*'Pricing & Mix'!H26*(1-'Pricing & Mix'!H28) -> 0 | I30: ='Pricing & Mix'!I24*'Pricing & Mix'!I26*(1-'Pricing & Mix'!I28) -> 0 | J30: ='Pricing & Mix'!J24*'Pricing & Mix'!J26*(1-'Pricing & Mix'!J28) -> 0 | ... AE30: ='Pricing & Mix'!AE24*'Pricing & Mix'!AE26*(1-'Pricing & Mix'!AE28) -> 104000 | AG30: =SUMIF($C$3:$AE$3,AG$3,$C30:$AE30) -> 0 | AH30: =SUMIF($C$3:$AE$3,AH$3,$C30:$AE30) -> 0 | AI30: =SUMIF($C$3:$AE$3,AI$3,$C30:$AE30) -> 12348.75 | AJ30: =SUMIF($C$3:$AE$3,AJ$3,$C30:$AE30) -> 33600 | AK30: =SUMIF($C$3:$AE$3,AK$3,$C30:$AE30) -> 65000 | AL30: =SUMIF($C$3:$AE$3,AL$3,$C30:$AE30) -> 104000
A31: DTC units -- Atlas | B31: units | C31: ='Pricing & Mix'!C24*'Pricing & Mix'!C27*(1-'Pricing & Mix'!C28) -> 0 | D31: ='Pricing & Mix'!D24*'Pricing & Mix'!D27*(1-'Pricing & Mix'!D28) -> 0 | E31: ='Pricing & Mix'!E24*'Pricing & Mix'!E27*(1-'Pricing & Mix'!E28) -> 0 | F31: ='Pricing & Mix'!F24*'Pricing & Mix'!F27*(1-'Pricing & Mix'!F28) -> 0 | G31: ='Pricing & Mix'!G24*'Pricing & Mix'!G27*(1-'Pricing & Mix'!G28) -> 0 | H31: ='Pricing & Mix'!H24*'Pricing & Mix'!H27*(1-'Pricing & Mix'!H28) -> 0 | I31: ='Pricing & Mix'!I24*'Pricing & Mix'!I27*(1-'Pricing & Mix'!I28) -> 0 | J31: ='Pricing & Mix'!J24*'Pricing & Mix'!J27*(1-'Pricing & Mix'!J28) -> 0 | ... AE31: ='Pricing & Mix'!AE24*'Pricing & Mix'!AE27*(1-'Pricing & Mix'!AE28) -> 39000 | AG31: =SUMIF($C$3:$AE$3,AG$3,$C31:$AE31) -> 0 | AH31: =SUMIF($C$3:$AE$3,AH$3,$C31:$AE31) -> 0 | AI31: =SUMIF($C$3:$AE$3,AI$3,$C31:$AE31) -> 3956.625 | AJ31: =SUMIF($C$3:$AE$3,AJ$3,$C31:$AE31) -> 12600 | AK31: =SUMIF($C$3:$AE$3,AK$3,$C31:$AE31) -> 24375 | AL31: =SUMIF($C$3:$AE$3,AL$3,$C31:$AE31) -> 39000
A32: Retail units -- Pebble | B32: units | C32: ='Pricing & Mix'!C24*'Pricing & Mix'!C25*'Pricing & Mix'!C28 -> 0 | D32: ='Pricing & Mix'!D24*'Pricing & Mix'!D25*'Pricing & Mix'!D28 -> 0 | E32: ='Pricing & Mix'!E24*'Pricing & Mix'!E25*'Pricing & Mix'!E28 -> 0 | F32: ='Pricing & Mix'!F24*'Pricing & Mix'!F25*'Pricing & Mix'!F28 -> 0 | G32: ='Pricing & Mix'!G24*'Pricing & Mix'!G25*'Pricing & Mix'!G28 -> 0 | H32: ='Pricing & Mix'!H24*'Pricing & Mix'!H25*'Pricing & Mix'!H28 -> 0 | I32: ='Pricing & Mix'!I24*'Pricing & Mix'!I25*'Pricing & Mix'!I28 -> 0 | J32: ='Pricing & Mix'!J24*'Pricing & Mix'!J25*'Pricing & Mix'!J28 -> 0 | ... AE32: ='Pricing & Mix'!AE24*'Pricing & Mix'!AE25*'Pricing & Mix'!AE28 -> 63000 | AG32: =SUMIF($C$3:$AE$3,AG$3,$C32:$AE32) -> 0 | AH32: =SUMIF($C$3:$AE$3,AH$3,$C32:$AE32) -> 0 | AI32: =SUMIF($C$3:$AE$3,AI$3,$C32:$AE32) -> 3520.375 | AJ32: =SUMIF($C$3:$AE$3,AJ$3,$C32:$AE32) -> 16200 | AK32: =SUMIF($C$3:$AE$3,AK$3,$C32:$AE32) -> 39375 | AL32: =SUMIF($C$3:$AE$3,AL$3,$C32:$AE32) -> 63000
A33: Retail units -- Square | B33: units | C33: ='Pricing & Mix'!C24*'Pricing & Mix'!C26*'Pricing & Mix'!C28 -> 0 | D33: ='Pricing & Mix'!D24*'Pricing & Mix'!D26*'Pricing & Mix'!D28 -> 0 | E33: ='Pricing & Mix'!E24*'Pricing & Mix'!E26*'Pricing & Mix'!E28 -> 0 | F33: ='Pricing & Mix'!F24*'Pricing & Mix'!F26*'Pricing & Mix'!F28 -> 0 | G33: ='Pricing & Mix'!G24*'Pricing & Mix'!G26*'Pricing & Mix'!G28 -> 0 | H33: ='Pricing & Mix'!H24*'Pricing & Mix'!H26*'Pricing & Mix'!H28 -> 0 | I33: ='Pricing & Mix'!I24*'Pricing & Mix'!I26*'Pricing & Mix'!I28 -> 0 | J33: ='Pricing & Mix'!J24*'Pricing & Mix'!J26*'Pricing & Mix'!J28 -> 0 | ... AE33: ='Pricing & Mix'!AE24*'Pricing & Mix'!AE26*'Pricing & Mix'!AE28 -> 56000 | AG33: =SUMIF($C$3:$AE$3,AG$3,$C33:$AE33) -> 0 | AH33: =SUMIF($C$3:$AE$3,AH$3,$C33:$AE33) -> 0 | AI33: =SUMIF($C$3:$AE$3,AI$3,$C33:$AE33) -> 3128.75 | AJ33: =SUMIF($C$3:$AE$3,AJ$3,$C33:$AE33) -> 14400 | AK33: =SUMIF($C$3:$AE$3,AK$3,$C33:$AE33) -> 35000 | AL33: =SUMIF($C$3:$AE$3,AL$3,$C33:$AE33) -> 56000
A34: Retail units -- Atlas | B34: units | C34: ='Pricing & Mix'!C24*'Pricing & Mix'!C27*'Pricing & Mix'!C28 -> 0 | D34: ='Pricing & Mix'!D24*'Pricing & Mix'!D27*'Pricing & Mix'!D28 -> 0 | E34: ='Pricing & Mix'!E24*'Pricing & Mix'!E27*'Pricing & Mix'!E28 -> 0 | F34: ='Pricing & Mix'!F24*'Pricing & Mix'!F27*'Pricing & Mix'!F28 -> 0 | G34: ='Pricing & Mix'!G24*'Pricing & Mix'!G27*'Pricing & Mix'!G28 -> 0 | H34: ='Pricing & Mix'!H24*'Pricing & Mix'!H27*'Pricing & Mix'!H28 -> 0 | I34: ='Pricing & Mix'!I24*'Pricing & Mix'!I27*'Pricing & Mix'!I28 -> 0 | J34: ='Pricing & Mix'!J24*'Pricing & Mix'!J27*'Pricing & Mix'!J28 -> 0 | ... AE34: ='Pricing & Mix'!AE24*'Pricing & Mix'!AE27*'Pricing & Mix'!AE28 -> 21000 | AG34: =SUMIF($C$3:$AE$3,AG$3,$C34:$AE34) -> 0 | AH34: =SUMIF($C$3:$AE$3,AH$3,$C34:$AE34) -> 0 | AI34: =SUMIF($C$3:$AE$3,AI$3,$C34:$AE34) -> 1098.375 | AJ34: =SUMIF($C$3:$AE$3,AJ$3,$C34:$AE34) -> 5400 | AK34: =SUMIF($C$3:$AE$3,AK$3,$C34:$AE34) -> 13125 | AL34: =SUMIF($C$3:$AE$3,AL$3,$C34:$AE34) -> 21000
A35: Pre-order units shipped -- Pebble | B35: units | C35: =(ks_units+pre_units)*sc_vol*Assumptions!C103*pre_mix_peb -> 0 | D35: =(ks_units+pre_units)*sc_vol*Assumptions!D103*pre_mix_peb -> 0 | E35: =(ks_units+pre_units)*sc_vol*Assumptions!E103*pre_mix_peb -> 0 | F35: =(ks_units+pre_units)*sc_vol*Assumptions!F103*pre_mix_peb -> 0 | G35: =(ks_units+pre_units)*sc_vol*Assumptions!G103*pre_mix_peb -> 0 | H35: =(ks_units+pre_units)*sc_vol*Assumptions!H103*pre_mix_peb -> 0 | I35: =(ks_units+pre_units)*sc_vol*Assumptions!I103*pre_mix_peb -> 0 | J35: =(ks_units+pre_units)*sc_vol*Assumptions!J103*pre_mix_peb -> 0 | ... AE35: =(ks_units+pre_units)*sc_vol*Assumptions!AE103*pre_mix_peb -> 0 | AG35: =SUMIF($C$3:$AE$3,AG$3,$C35:$AE35) -> 0 | AH35: =SUMIF($C$3:$AE$3,AH$3,$C35:$AE35) -> 1957.5 | AI35: =SUMIF($C$3:$AE$3,AI$3,$C35:$AE35) -> 292.5 | AJ35: =SUMIF($C$3:$AE$3,AJ$3,$C35:$AE35) -> 0 | AK35: =SUMIF($C$3:$AE$3,AK$3,$C35:$AE35) -> 0 | AL35: =SUMIF($C$3:$AE$3,AL$3,$C35:$AE35) -> 0
A36: Pre-order units shipped -- Square | B36: units | C36: =(ks_units+pre_units)*sc_vol*Assumptions!C103*(1-pre_mix_peb-pre_mix_atl) -> 0 | D36: =(ks_units+pre_units)*sc_vol*Assumptions!D103*(1-pre_mix_peb-pre_mix_atl) -> 0 | E36: =(ks_units+pre_units)*sc_vol*Assumptions!E103*(1-pre_mix_peb-pre_mix_atl) -> 0 | F36: =(ks_units+pre_units)*sc_vol*Assumptions!F103*(1-pre_mix_peb-pre_mix_atl) -> 0 | G36: =(ks_units+pre_units)*sc_vol*Assumptions!G103*(1-pre_mix_peb-pre_mix_atl) -> 0 | H36: =(ks_units+pre_units)*sc_vol*Assumptions!H103*(1-pre_mix_peb-pre_mix_atl) -> 0 | I36: =(ks_units+pre_units)*sc_vol*Assumptions!I103*(1-pre_mix_peb-pre_mix_atl) -> 0 | J36: =(ks_units+pre_units)*sc_vol*Assumptions!J103*(1-pre_mix_peb-pre_mix_atl) -> 0 | ... AE36: =(ks_units+pre_units)*sc_vol*Assumptions!AE103*(1-pre_mix_peb-pre_mix_atl) -> 0 | AG36: =SUMIF($C$3:$AE$3,AG$3,$C36:$AE36) -> 0 | AH36: =SUMIF($C$3:$AE$3,AH$3,$C36:$AE36) -> 1740 | AI36: =SUMIF($C$3:$AE$3,AI$3,$C36:$AE36) -> 260 | AJ36: =SUMIF($C$3:$AE$3,AJ$3,$C36:$AE36) -> 0 | AK36: =SUMIF($C$3:$AE$3,AK$3,$C36:$AE36) -> 0 | AL36: =SUMIF($C$3:$AE$3,AL$3,$C36:$AE36) -> 0
A37: Pre-order units shipped -- Atlas | B37: units | C37: =(ks_units+pre_units)*sc_vol*Assumptions!C105*pre_mix_atl -> 0 | D37: =(ks_units+pre_units)*sc_vol*Assumptions!D105*pre_mix_atl -> 0 | E37: =(ks_units+pre_units)*sc_vol*Assumptions!E105*pre_mix_atl -> 0 | F37: =(ks_units+pre_units)*sc_vol*Assumptions!F105*pre_mix_atl -> 0 | G37: =(ks_units+pre_units)*sc_vol*Assumptions!G105*pre_mix_atl -> 0 | H37: =(ks_units+pre_units)*sc_vol*Assumptions!H105*pre_mix_atl -> 0 | I37: =(ks_units+pre_units)*sc_vol*Assumptions!I105*pre_mix_atl -> 0 | J37: =(ks_units+pre_units)*sc_vol*Assumptions!J105*pre_mix_atl -> 0 | ... AE37: =(ks_units+pre_units)*sc_vol*Assumptions!AE105*pre_mix_atl -> 0 | AG37: =SUMIF($C$3:$AE$3,AG$3,$C37:$AE37) -> 0 | AH37: =SUMIF($C$3:$AE$3,AH$3,$C37:$AE37) -> 0 | AI37: =SUMIF($C$3:$AE$3,AI$3,$C37:$AE37) -> 750 | AJ37: =SUMIF($C$3:$AE$3,AJ$3,$C37:$AE37) -> 0 | AK37: =SUMIF($C$3:$AE$3,AK$3,$C37:$AE37) -> 0 | AL37: =SUMIF($C$3:$AE$3,AL$3,$C37:$AE37) -> 0
A38: Pre-order (KS + late pledge) units shipped | B38: units | C38: ='Pricing & Mix'!C35+'Pricing & Mix'!C36+'Pricing & Mix'!C37 -> 0 | D38: ='Pricing & Mix'!D35+'Pricing & Mix'!D36+'Pricing & Mix'!D37 -> 0 | E38: ='Pricing & Mix'!E35+'Pricing & Mix'!E36+'Pricing & Mix'!E37 -> 0 | F38: ='Pricing & Mix'!F35+'Pricing & Mix'!F36+'Pricing & Mix'!F37 -> 0 | G38: ='Pricing & Mix'!G35+'Pricing & Mix'!G36+'Pricing & Mix'!G37 -> 0 | H38: ='Pricing & Mix'!H35+'Pricing & Mix'!H36+'Pricing & Mix'!H37 -> 0 | I38: ='Pricing & Mix'!I35+'Pricing & Mix'!I36+'Pricing & Mix'!I37 -> 0 | J38: ='Pricing & Mix'!J35+'Pricing & Mix'!J36+'Pricing & Mix'!J37 -> 0 | ... AE38: ='Pricing & Mix'!AE35+'Pricing & Mix'!AE36+'Pricing & Mix'!AE37 -> 0 | AG38: =SUMIF($C$3:$AE$3,AG$3,$C38:$AE38) -> 0 | AH38: =SUMIF($C$3:$AE$3,AH$3,$C38:$AE38) -> 3697.5 | AI38: =SUMIF($C$3:$AE$3,AI$3,$C38:$AE38) -> 1302.5 | AJ38: =SUMIF($C$3:$AE$3,AJ$3,$C38:$AE38) -> 0 | AK38: =SUMIF($C$3:$AE$3,AK$3,$C38:$AE38) -> 0 | AL38: =SUMIF($C$3:$AE$3,AL$3,$C38:$AE38) -> 0
A39: Total units shipped -- Pebble | B39: units | C39: ='Pricing & Mix'!C29+'Pricing & Mix'!C32+'Pricing & Mix'!C35 -> 0 | D39: ='Pricing & Mix'!D29+'Pricing & Mix'!D32+'Pricing & Mix'!D35 -> 0 | E39: ='Pricing & Mix'!E29+'Pricing & Mix'!E32+'Pricing & Mix'!E35 -> 0 | F39: ='Pricing & Mix'!F29+'Pricing & Mix'!F32+'Pricing & Mix'!F35 -> 0 | G39: ='Pricing & Mix'!G29+'Pricing & Mix'!G32+'Pricing & Mix'!G35 -> 0 | H39: ='Pricing & Mix'!H29+'Pricing & Mix'!H32+'Pricing & Mix'!H35 -> 0 | I39: ='Pricing & Mix'!I29+'Pricing & Mix'!I32+'Pricing & Mix'!I35 -> 0 | J39: ='Pricing & Mix'!J29+'Pricing & Mix'!J32+'Pricing & Mix'!J35 -> 0 | ... AE39: ='Pricing & Mix'!AE29+'Pricing & Mix'!AE32+'Pricing & Mix'!AE35 -> 180000 | AG39: =SUMIF($C$3:$AE$3,AG$3,$C39:$AE39) -> 0 | AH39: =SUMIF($C$3:$AE$3,AH$3,$C39:$AE39) -> 1957.5 | AI39: =SUMIF($C$3:$AE$3,AI$3,$C39:$AE39) -> 17710 | AJ39: =SUMIF($C$3:$AE$3,AJ$3,$C39:$AE39) -> 54000 | AK39: =SUMIF($C$3:$AE$3,AK$3,$C39:$AE39) -> 112500 | AL39: =SUMIF($C$3:$AE$3,AL$3,$C39:$AE39) -> 180000
A40: Total units shipped -- Square | B40: units | C40: ='Pricing & Mix'!C30+'Pricing & Mix'!C33+'Pricing & Mix'!C36 -> 0 | D40: ='Pricing & Mix'!D30+'Pricing & Mix'!D33+'Pricing & Mix'!D36 -> 0 | E40: ='Pricing & Mix'!E30+'Pricing & Mix'!E33+'Pricing & Mix'!E36 -> 0 | F40: ='Pricing & Mix'!F30+'Pricing & Mix'!F33+'Pricing & Mix'!F36 -> 0 | G40: ='Pricing & Mix'!G30+'Pricing & Mix'!G33+'Pricing & Mix'!G36 -> 0 | H40: ='Pricing & Mix'!H30+'Pricing & Mix'!H33+'Pricing & Mix'!H36 -> 0 | I40: ='Pricing & Mix'!I30+'Pricing & Mix'!I33+'Pricing & Mix'!I36 -> 0 | J40: ='Pricing & Mix'!J30+'Pricing & Mix'!J33+'Pricing & Mix'!J36 -> 0 | ... AE40: ='Pricing & Mix'!AE30+'Pricing & Mix'!AE33+'Pricing & Mix'!AE36 -> 160000 | AG40: =SUMIF($C$3:$AE$3,AG$3,$C40:$AE40) -> 0 | AH40: =SUMIF($C$3:$AE$3,AH$3,$C40:$AE40) -> 1740 | AI40: =SUMIF($C$3:$AE$3,AI$3,$C40:$AE40) -> 15737.5 | AJ40: =SUMIF($C$3:$AE$3,AJ$3,$C40:$AE40) -> 48000 | AK40: =SUMIF($C$3:$AE$3,AK$3,$C40:$AE40) -> 100000 | AL40: =SUMIF($C$3:$AE$3,AL$3,$C40:$AE40) -> 160000
A41: Total units shipped -- Atlas | B41: units | C41: ='Pricing & Mix'!C31+'Pricing & Mix'!C34+'Pricing & Mix'!C37 -> 0 | D41: ='Pricing & Mix'!D31+'Pricing & Mix'!D34+'Pricing & Mix'!D37 -> 0 | E41: ='Pricing & Mix'!E31+'Pricing & Mix'!E34+'Pricing & Mix'!E37 -> 0 | F41: ='Pricing & Mix'!F31+'Pricing & Mix'!F34+'Pricing & Mix'!F37 -> 0 | G41: ='Pricing & Mix'!G31+'Pricing & Mix'!G34+'Pricing & Mix'!G37 -> 0 | H41: ='Pricing & Mix'!H31+'Pricing & Mix'!H34+'Pricing & Mix'!H37 -> 0 | I41: ='Pricing & Mix'!I31+'Pricing & Mix'!I34+'Pricing & Mix'!I37 -> 0 | J41: ='Pricing & Mix'!J31+'Pricing & Mix'!J34+'Pricing & Mix'!J37 -> 0 | ... AE41: ='Pricing & Mix'!AE31+'Pricing & Mix'!AE34+'Pricing & Mix'!AE37 -> 60000 | AG41: =SUMIF($C$3:$AE$3,AG$3,$C41:$AE41) -> 0 | AH41: =SUMIF($C$3:$AE$3,AH$3,$C41:$AE41) -> 0 | AI41: =SUMIF($C$3:$AE$3,AI$3,$C41:$AE41) -> 5805 | AJ41: =SUMIF($C$3:$AE$3,AJ$3,$C41:$AE41) -> 18000 | AK41: =SUMIF($C$3:$AE$3,AK$3,$C41:$AE41) -> 37500 | AL41: =SUMIF($C$3:$AE$3,AL$3,$C41:$AE41) -> 60000
A42: TOTAL UNITS SHIPPED | B42: units | C42: ='Pricing & Mix'!C39+'Pricing & Mix'!C40+'Pricing & Mix'!C41 -> 0 | D42: ='Pricing & Mix'!D39+'Pricing & Mix'!D40+'Pricing & Mix'!D41 -> 0 | E42: ='Pricing & Mix'!E39+'Pricing & Mix'!E40+'Pricing & Mix'!E41 -> 0 | F42: ='Pricing & Mix'!F39+'Pricing & Mix'!F40+'Pricing & Mix'!F41 -> 0 | G42: ='Pricing & Mix'!G39+'Pricing & Mix'!G40+'Pricing & Mix'!G41 -> 0 | H42: ='Pricing & Mix'!H39+'Pricing & Mix'!H40+'Pricing & Mix'!H41 -> 0 | I42: ='Pricing & Mix'!I39+'Pricing & Mix'!I40+'Pricing & Mix'!I41 -> 0 | J42: ='Pricing & Mix'!J39+'Pricing & Mix'!J40+'Pricing & Mix'!J41 -> 0 | ... AE42: ='Pricing & Mix'!AE39+'Pricing & Mix'!AE40+'Pricing & Mix'!AE41 -> 400000 | AG42: =SUMIF($C$3:$AE$3,AG$3,$C42:$AE42) -> 0 | AH42: =SUMIF($C$3:$AE$3,AH$3,$C42:$AE42) -> 3697.5 | AI42: =SUMIF($C$3:$AE$3,AI$3,$C42:$AE42) -> 39252.5 | AJ42: =SUMIF($C$3:$AE$3,AJ$3,$C42:$AE42) -> 120000 | AK42: =SUMIF($C$3:$AE$3,AK$3,$C42:$AE42) -> 250000 | AL42: =SUMIF($C$3:$AE$3,AL$3,$C42:$AE42) -> 400000
A43: DTC regular units | B43: units | C43: ='Pricing & Mix'!C29+'Pricing & Mix'!C30+'Pricing & Mix'!C31 -> 0 | D43: ='Pricing & Mix'!D29+'Pricing & Mix'!D30+'Pricing & Mix'!D31 -> 0 | E43: ='Pricing & Mix'!E29+'Pricing & Mix'!E30+'Pricing & Mix'!E31 -> 0 | F43: ='Pricing & Mix'!F29+'Pricing & Mix'!F30+'Pricing & Mix'!F31 -> 0 | G43: ='Pricing & Mix'!G29+'Pricing & Mix'!G30+'Pricing & Mix'!G31 -> 0 | H43: ='Pricing & Mix'!H29+'Pricing & Mix'!H30+'Pricing & Mix'!H31 -> 0 | I43: ='Pricing & Mix'!I29+'Pricing & Mix'!I30+'Pricing & Mix'!I31 -> 0 | J43: ='Pricing & Mix'!J29+'Pricing & Mix'!J30+'Pricing & Mix'!J31 -> 0 | ... AE43: ='Pricing & Mix'!AE29+'Pricing & Mix'!AE30+'Pricing & Mix'!AE31 -> 260000 | AG43: =SUMIF($C$3:$AE$3,AG$3,$C43:$AE43) -> 0 | AH43: =SUMIF($C$3:$AE$3,AH$3,$C43:$AE43) -> 0 | AI43: =SUMIF($C$3:$AE$3,AI$3,$C43:$AE43) -> 30202.5 | AJ43: =SUMIF($C$3:$AE$3,AJ$3,$C43:$AE43) -> 84000 | AK43: =SUMIF($C$3:$AE$3,AK$3,$C43:$AE43) -> 162500 | AL43: =SUMIF($C$3:$AE$3,AL$3,$C43:$AE43) -> 260000
...

Sheet Unit Economics
A1: Unit economics per SKU -- FY2028 basis (live). DTC = direct web/app sale; Retail = sell-in to retailer.
B3: Pebble DTC | C3: Square DTC | D3: Atlas DTC | E3: Pebble Retail | F3: Square Retail | G3: Atlas Retail | I3: Notes
A4: MSRP | B4: =msrp_peb*sc_price -> 149 | C4: =msrp_sq*sc_price -> 299 | D4: =msrp_atl*sc_price -> 599 | E4: =msrp_peb*sc_price -> 149 | F4: =msrp_sq*sc_price -> 299 | G4: =msrp_atl*sc_price -> 599
A5: Discount / retailer margin | B5: =-B4*dtc_disc -> -8.94 | C5: =-C4*dtc_disc -> -17.94 | D5: =-D4*dtc_disc -> -35.94 | E5: =-E4*retail_margin -> -56.62 | F5: =-F4*retail_margin -> -113.62 | G5: =-G4*retail_margin -> -227.62 | I5: DTC promo vs retailer margin.
A6: Returns allowance | B6: =-(B4+B5)*returns_pct -> -5.6024 | C6: =-(C4+C5)*returns_pct -> -11.2424 | D6: =-(D4+D5)*returns_pct -> -22.5224 | E6: =-(E4+E5)*returns_pct -> -3.6952 | F6: =-(F4+F5)*returns_pct -> -7.4152 | G6: =-(G4+G5)*returns_pct -> -14.8552
A7: Net revenue per unit | B7: =B4+B5+B6 -> 134.4576 | C7: =C4+C5+C6 -> 269.8176 | D7: =D4+D5+D6 -> 540.5376 | E7: =E4+E5+E6 -> 88.6848 | F7: =F4+F5+F6 -> 177.9648 | G7: =G4+G5+G6 -> 356.5248
A8: Landed COGS (BOM + assembly + pack + freight/duty) | B8: =-(bom_peb+asm_peb+pkg_peb)*(1+freight_duty)*sc_cogs -> -62.6503 | C8: =-(bom_sq+asm_sq+pkg_sq)*(1+freight_duty)*sc_cogs -> -227.1591 | D8: =-(bom_atl+asm_atl+pkg_atl)*(1+freight_duty)*sc_cogs -> -317.3925 | E8: =-(bom_peb+asm_peb+pkg_peb)*(1+freight_duty)*sc_cogs -> -62.6503 | F8: =-(bom_sq+asm_sq+pkg_sq)*(1+freight_duty)*sc_cogs -> -227.1591 | G8: =-(bom_atl+asm_atl+pkg_atl)*(1+freight_duty)*sc_cogs -> -317.3925 | I8: 2027-28 cost basis (index 1.00).
A9: Fulfilment / distribution | B9: =-dtc_ship -> -11 | C9: =-dtc_ship -> -11 | D9: =-dtc_ship -> -11 | E9: =-retail_dist -> -4 | F9: =-retail_dist -> -4 | G9: =-retail_dist -> -4
A10: Payment processing | B10: =-((B4+B5)*pay_pct+pay_fixed) -> -4.36174 | C10: =-((C4+C5)*pay_pct+pay_fixed) -> -8.45074 | D10: =-((D4+D5)*pay_pct+pay_fixed) -> -16.62874 | E10: =0 -> 0 | F10: =0 -> 0 | G10: =0 -> 0
A11: Warranty reserve | B11: =-(B4+B5)*warranty_pct -> -2.8012 | C11: =-(C4+C5)*warranty_pct -> -5.6212 | D11: =-(D4+D5)*warranty_pct -> -11.2612 | E11: =-(E4+E5)*warranty_pct -> -1.8476 | F11: =-(F4+F5)*warranty_pct -> -3.7076 | G11: =-(G4+G5)*warranty_pct -> -7.4276
A12: Hardware gross profit per unit | B12: =B7+B8+B9+B10+B11 -> 53.64436 | C12: =C7+C8+C9+C10+C11 -> 17.58656 | D12: =D7+D8+D9+D10+D11 -> 184.25516 | E12: =E7+E8+E9+E10+E11 -> 20.1869 | F12: =F7+F8+F9+F10+F11 -> -56.9019 | G12: =G7+G8+G9+G10+G11 -> 27.7047
A13: Hardware gross margin % | B13: =IF(B7>0,B12/B7,0) -> 0.3989686 | C13: =IF(C7>0,C12/C7,0) -> 0.06517944 | D13: =IF(D7>0,D12/D7,0) -> 0.3408739 | E13: =IF(E7>0,E12/E7,0) -> 0.22762525 | F13: =IF(F7>0,F12/F7,0) -> -0.31973682 | G13: =IF(G7>0,G12/G7,0) -> 0.077707638
A14: Acquisition cost (paid CAC DTC; co-op for retail) | B14: =-Assumptions!V113*sc_cac -> -60 | C14: =-Assumptions!V113*sc_cac -> -60 | D14: =-Assumptions!V113*sc_cac -> -60 | E14: =-(E4+E5)*retail_coop -> -5.5428 | F14: =-(F4+F5)*retail_coop -> -11.1228 | G14: =-(G4+G5)*retail_coop -> -22.2828 | I14: FY2028 CAC.
A15: Hardware contribution after acquisition | B15: =B12+B14 -> -6.35564 | C15: =C12+C14 -> -42.41344 | D15: =D12+D14 -> 124.25516 | E15: =E12+E14 -> 14.6441 | F15: =F12+F14 -> -68.0247 | G15: =G12+G14 -> 5.4219
A16: Accessories gross profit per device | B16: =acc_attach*acc_aov*sc_price*(1-acc_cogs_pct) -> 8.37 | C16: =acc_attach*acc_aov*sc_price*(1-acc_cogs_pct) -> 8.37 | D16: =acc_attach*acc_aov*sc_price*(1-acc_cogs_pct) -> 8.37 | E16: =acc_attach*acc_aov*sc_price*(1-acc_cogs_pct) -> 8.37 | F16: =acc_attach*acc_aov*sc_price*(1-acc_cogs_pct) -> 8.37 | G16: =acc_attach*acc_aov*sc_price*(1-acc_cogs_pct) -> 8.37
A17: Free 3-month trial cost (cloud) | B17: =-trial_months*'Cloud & AI COGS'!V10 -> -6.048 | C17: =-trial_months*'Cloud & AI COGS'!V10 -> -6.048 | D17: =-trial_months*'Cloud & AI COGS'!V10 -> -6.048 | E17: =-trial_months*'Cloud & AI COGS'!V10 -> -6.048 | F17: =-trial_months*'Cloud & AI COGS'!V10 -> -6.048 | G17: =-trial_months*'Cloud & AI COGS'!V10 -> -6.048 | I17: Every device gets 3 months of Explorer.
A18: Paid attach after trial | B18: =MIN(1,attach_peb*sc_attach) -> 0.28 | C18: =MIN(1,attach_sq*sc_attach) -> 0.4 | D18: =MIN(1,attach_atl*sc_attach) -> 0.55 | E18: =MIN(1,attach_peb*sc_attach) -> 0.28 | F18: =MIN(1,attach_sq*sc_attach) -> 0.4 | G18: =MIN(1,attach_atl*sc_attach) -> 0.55
A19: Subscription gross profit per paid month | B19: =sub_price*arpu_real*sc_price*(1-sub_pay_fee)-'Cloud & AI COGS'!V10 -> 5.888088 | C19: =sub_price*arpu_real*sc_price*(1-sub_pay_fee)-'Cloud & AI COGS'!V10 -> 5.888088 | D19: =sub_price*arpu_real*sc_price*(1-sub_pay_fee)-'Cloud & AI COGS'!V10 -> 5.888088 | E19: =sub_price*arpu_real*sc_price*(1-sub_pay_fee)-'Cloud & AI COGS'!V10 -> 5.888088 | F19: =sub_price*arpu_real*sc_price*(1-sub_pay_fee)-'Cloud & AI COGS'!V10 -> 5.888088 | G19: =sub_price*arpu_real*sc_price*(1-sub_pay_fee)-'Cloud & AI COGS'!V10 -> 5.888088
A20: Expected paid lifetime (months) = 1/churn | B20: =1/MIN(0.5,churn*sc_churn) -> 16.666667 | C20: =1/MIN(0.5,churn*sc_churn) -> 16.666667 | D20: =1/MIN(0.5,churn*sc_churn) -> 16.666667 | E20: =1/MIN(0.5,churn*sc_churn) -> 16.666667 | F20: =1/MIN(0.5,churn*sc_churn) -> 16.666667 | G20: =1/MIN(0.5,churn*sc_churn) -> 16.666667
A21: Subscription LTV (gross profit, undiscounted) | B21: =B18*B19*B20 -> 27.477744 | C21: =C18*C19*C20 -> 39.25392 | D21: =D18*D19*D20 -> 53.97414 | E21: =E18*E19*E20 -> 27.477744 | F21: =F18*F19*F20 -> 39.25392 | G21: =G18*G19*G20 -> 53.97414
A22: Affiliate gross profit over device life | B22: =Assumptions!V112/device_inactive -> 15 | C22: =Assumptions!V112/device_inactive -> 15 | D22: =Assumptions!V112/device_inactive -> 15 | E22: =Assumptions!V112/device_inactive -> 15 | F22: =Assumptions!V112/device_inactive -> 15 | G22: =Assumptions!V112/device_inactive -> 15 | I22: Rate x expected active life (1/inactivity).
A23: TOTAL LIFETIME CONTRIBUTION PER DEVICE | B23: =B15+B16+B17+B21+B22 -> 38.444104 | C23: =C15+C16+C17+C21+C22 -> 14.16248 | D23: =D15+D16+D17+D21+D22 -> 195.5513 | E23: =E15+E16+E17+E21+E22 -> 59.443844 | F23: =F15+F16+F17+F21+F22 -> -11.44878 | G23: =G15+G16+G17+G21+G22 -> 76.71804
A24: Lifetime contribution / acquisition cost (LTV:CAC) | B24: =IF(B14<0,(B23-B14)/-B14,0) -> 1.6407351 | C24: =IF(C14<0,(C23-C14)/-C14,0) -> 1.2360413 | D24: =IF(D14<0,(D23-D14)/-D14,0) -> 4.2591883 | E24: =IF(E14<0,(E23-E14)/-E14,0) -> 11.724515 | F24: =IF(F14<0,(F23-F14)/-F14,0) -> -0.029307369 | G24: =IF(G14<0,(G23-G14)/-G14,0) -> 4.4429264 | I24: Contribution before CAC divided by CAC.
A25: Payback on CAC (months after purchase) | B25: =IF(B12+B16>=-B14,0,(-B14-B12-B16)/MAX(0.01,B18*B19)) -> 0 | C25: =IF(C12+C16>=-C14,0,(-C14-C12-C16)/MAX(0.01,C18*C19)) -> 14.45437 | D25: =IF(D12+D16>=-D14,0,(-D14-D12-D16)/MAX(0.01,D18*D19)) -> 0 | E25: =IF(E12+E16>=-E14,0,(-E14-E12-E16)/MAX(0.01,E18*E19)) -> 0 | F25: =IF(F12+F16>=-F14,0,(-F14-F12-F16)/MAX(0.01,F18*F19)) -> 25.328553 | G25: =IF(G12+G16>=-G14,0,(-G14-G12-G16)/MAX(0.01,G18*G19)) -> 0 | I25: 0 = paid back at sale by hardware margin.
A29: Sensitivity: DTC hardware gross margin % by price (rows) and landed-COGS change (cols)
A30: Pebble: price \ COGS delta | B30: -0.15 | C30: -0.1 | D30: -0.05 | E30: 0 | F30: 0.05 | G30: 0.1 | H30: 0.2
A31: 119 | B31: =1-((bom_peb+asm_peb+pkg_peb)*(1+freight_duty)*(1+B$30)+dtc_ship+$A31*(1-dtc_disc)*(pay_pct+warranty_pct)+pay_fixed)/($A31*(1-dtc_disc)*(1-returns_pct)) -> 0.34782787 | C31: =1-((bom_peb+asm_peb+pkg_peb)*(1+freight_duty)*(1+C$30)+dtc_ship+$A31*(1-dtc_disc)*(pay_pct+warranty_pct)+pay_fixed)/($A31*(1-dtc_disc)*(1-returns_pct)) -> 0.31865716 | D31: =1-((bom_peb+asm_peb+pkg_peb)*(1+freight_duty)*(1+D$30)+dtc_ship+$A31*(1-dtc_disc)*(pay_pct+warranty_pct)+pay_fixed)/($A31*(1-dtc_disc)*(1-returns_pct)) -> 0.28948644 | E31: =1-((bom_peb+asm_peb+pkg_peb)*(1+freight_duty)*(1+E$30)+dtc_ship+$A31*(1-dtc_disc)*(pay_pct+warranty_pct)+pay_fixed)/($A31*(1-dtc_disc)*(1-returns_pct)) -> 0.26031572 | F31: =1-((bom_peb+asm_peb+pkg_peb)*(1+freight_duty)*(1+F$30)+dtc_ship+$A31*(1-dtc_disc)*(pay_pct+warranty_pct)+pay_fixed)/($A31*(1-dtc_disc)*(1-returns_pct)) -> 0.231145 | G31: =1-((bom_peb+asm_peb+pkg_peb)*(1+freight_duty)*(1+G$30)+dtc_ship+$A31*(1-dtc_disc)*(pay_pct+warranty_pct)+pay_fixed)/($A31*(1-dtc_disc)*(1-returns_pct)) -> 0.20197429 | H31: =1-((bom_peb+asm_peb+pkg_peb)*(1+freight_duty)*(1+H$30)+dtc_ship+$A31*(1-dtc_disc)*(pay_pct+warranty_pct)+pay_fixed)/($A31*(1-dtc_disc)*(1-returns_pct)) -> 0.14363285
A32: 129 | B32: =1-((bom_peb+asm_peb+pkg_peb)*(1+freight_duty)*(1+B$30)+dtc_ship+$A32*(1-dtc_disc)*(pay_pct+warranty_pct)+pay_fixed)/($A32*(1-dtc_disc)*(1-returns_pct)) -> 0.39442713 | C32: =1-((bom_peb+asm_peb+pkg_peb)*(1+freight_duty)*(1+C$30)+dtc_ship+$A32*(1-dtc_disc)*(pay_pct+warranty_pct)+pay_fixed)/($A32*(1-dtc_disc)*(1-returns_pct)) -> 0.36751771 | D32: =1-((bom_peb+asm_peb+pkg_peb)*(1+freight_duty)*(1+D$30)+dtc_ship+$A32*(1-dtc_disc)*(pay_pct+warranty_pct)+pay_fixed)/($A32*(1-dtc_disc)*(1-returns_pct)) -> 0.34060829 | E32: =1-((bom_peb+asm_peb+pkg_peb)*(1+freight_duty)*(1+E$30)+dtc_ship+$A32*(1-dtc_disc)*(pay_pct+warranty_pct)+pay_fixed)/($A32*(1-dtc_disc)*(1-returns_pct)) -> 0.31369887 | F32: =1-((bom_peb+asm_peb+pkg_peb)*(1+freight_duty)*(1+F$30)+dtc_ship+$A32*(1-dtc_disc)*(pay_pct+warranty_pct)+pay_fixed)/($A32*(1-dtc_disc)*(1-returns_pct)) -> 0.28678945 | G32: =1-((bom_peb+asm_peb+pkg_peb)*(1+freight_duty)*(1+G$30)+dtc_ship+$A32*(1-dtc_disc)*(pay_pct+warranty_pct)+pay_fixed)/($A32*(1-dtc_disc)*(1-returns_pct)) -> 0.25988003 | H32: =1-((bom_peb+asm_peb+pkg_peb)*(1+freight_duty)*(1+H$30)+dtc_ship+$A32*(1-dtc_disc)*(pay_pct+warranty_pct)+pay_fixed)/($A32*(1-dtc_disc)*(1-returns_pct)) -> 0.20606118
A33: 139 | B33: =1-((bom_peb+asm_peb+pkg_peb)*(1+freight_duty)*(1+B$30)+dtc_ship+$A33*(1-dtc_disc)*(pay_pct+warranty_pct)+pay_fixed)/($A33*(1-dtc_disc)*(1-returns_pct)) -> 0.43432147 | C33: =1-((bom_peb+asm_peb+pkg_peb)*(1+freight_duty)*(1+C$30)+dtc_ship+$A33*(1-dtc_disc)*(pay_pct+warranty_pct)+pay_fixed)/($A33*(1-dtc_disc)*(1-returns_pct)) -> 0.40934797 | D33: =1-((bom_peb+asm_peb+pkg_peb)*(1+freight_duty)*(1+D$30)+dtc_ship+$A33*(1-dtc_disc)*(pay_pct+warranty_pct)+pay_fixed)/($A33*(1-dtc_disc)*(1-returns_pct)) -> 0.38437448 | E33: =1-((bom_peb+asm_peb+pkg_peb)*(1+freight_duty)*(1+E$30)+dtc_ship+$A33*(1-dtc_disc)*(pay_pct+warranty_pct)+pay_fixed)/($A33*(1-dtc_disc)*(1-returns_pct)) -> 0.35940099 | F33: =1-((bom_peb+asm_peb+pkg_peb)*(1+freight_duty)*(1+F$30)+dtc_ship+$A33*(1-dtc_disc)*(pay_pct+warranty_pct)+pay_fixed)/($A33*(1-dtc_disc)*(1-returns_pct)) -> 0.3344275 | G33: =1-((bom_peb+asm_peb+pkg_peb)*(1+freight_duty)*(1+G$30)+dtc_ship+$A33*(1-dtc_disc)*(pay_pct+warranty_pct)+pay_fixed)/($A33*(1-dtc_disc)*(1-returns_pct)) -> 0.30945401 | H33: =1-((bom_peb+asm_peb+pkg_peb)*(1+freight_duty)*(1+H$30)+dtc_ship+$A33*(1-dtc_disc)*(pay_pct+warranty_pct)+pay_fixed)/($A33*(1-dtc_disc)*(1-returns_pct)) -> 0.25950702
A34: 149 | B34: =1-((bom_peb+asm_peb+pkg_peb)*(1+freight_duty)*(1+B$30)+dtc_ship+$A34*(1-dtc_disc)*(pay_pct+warranty_pct)+pay_fixed)/($A34*(1-dtc_disc)*(1-returns_pct)) -> 0.46886085 | C34: =1-((bom_peb+asm_peb+pkg_peb)*(1+freight_duty)*(1+C$30)+dtc_ship+$A34*(1-dtc_disc)*(pay_pct+warranty_pct)+pay_fixed)/($A34*(1-dtc_disc)*(1-returns_pct)) -> 0.44556343 | D34: =1-((bom_peb+asm_peb+pkg_peb)*(1+freight_duty)*(1+D$30)+dtc_ship+$A34*(1-dtc_disc)*(pay_pct+warranty_pct)+pay_fixed)/($A34*(1-dtc_disc)*(1-returns_pct)) -> 0.42226602 | E34: =1-((bom_peb+asm_peb+pkg_peb)*(1+freight_duty)*(1+E$30)+dtc_ship+$A34*(1-dtc_disc)*(pay_pct+warranty_pct)+pay_fixed)/($A34*(1-dtc_disc)*(1-returns_pct)) -> 0.3989686 | F34: =1-((bom_peb+asm_peb+pkg_peb)*(1+freight_duty)*(1+F$30)+dtc_ship+$A34*(1-dtc_disc)*(pay_pct+warranty_pct)+pay_fixed)/($A34*(1-dtc_disc)*(1-returns_pct)) -> 0.37567118 | G34: =1-((bom_peb+asm_peb+pkg_peb)*(1+freight_duty)*(1+G$30)+dtc_ship+$A34*(1-dtc_disc)*(pay_pct+warranty_pct)+pay_fixed)/($A34*(1-dtc_disc)*(1-returns_pct)) -> 0.35237376 | H34: =1-((bom_peb+asm_peb+pkg_peb)*(1+freight_duty)*(1+H$30)+dtc_ship+$A34*(1-dtc_disc)*(pay_pct+warranty_pct)+pay_fixed)/($A34*(1-dtc_disc)*(1-returns_pct)) -> 0.30577892
A35: 169 | B35: =1-((bom_peb+asm_peb+pkg_peb)*(1+freight_duty)*(1+B$30)+dtc_ship+$A35*(1-dtc_disc)*(pay_pct+warranty_pct)+pay_fixed)/($A35*(1-dtc_disc)*(1-returns_pct)) -> 0.52567712 | C35: =1-((bom_peb+asm_peb+pkg_peb)*(1+freight_duty)*(1+C$30)+dtc_ship+$A35*(1-dtc_disc)*(pay_pct+warranty_pct)+pay_fixed)/($A35*(1-dtc_disc)*(1-returns_pct)) -> 0.50513679 | D35: =1-((bom_peb+asm_peb+pkg_peb)*(1+freight_duty)*(1+D$30)+dtc_ship+$A35*(1-dtc_disc)*(pay_pct+warranty_pct)+pay_fixed)/($A35*(1-dtc_disc)*(1-returns_pct)) -> 0.48459647 | E35: =1-((bom_peb+asm_peb+pkg_peb)*(1+freight_duty)*(1+E$30)+dtc_ship+$A35*(1-dtc_disc)*(pay_pct+warranty_pct)+pay_fixed)/($A35*(1-dtc_disc)*(1-returns_pct)) -> 0.46405614 | F35: =1-((bom_peb+asm_peb+pkg_peb)*(1+freight_duty)*(1+F$30)+dtc_ship+$A35*(1-dtc_disc)*(pay_pct+warranty_pct)+pay_fixed)/($A35*(1-dtc_disc)*(1-returns_pct)) -> 0.44351581 | G35: =1-((bom_peb+asm_peb+pkg_peb)*(1+freight_duty)*(1+G$30)+dtc_ship+$A35*(1-dtc_disc)*(pay_pct+warranty_pct)+pay_fixed)/($A35*(1-dtc_disc)*(1-returns_pct)) -> 0.42297548 | H35: =1-((bom_peb+asm_peb+pkg_peb)*(1+freight_duty)*(1+H$30)+dtc_ship+$A35*(1-dtc_disc)*(pay_pct+warranty_pct)+pay_fixed)/($A35*(1-dtc_disc)*(1-returns_pct)) -> 0.38189483
A36: 179 | B36: =1-((bom_peb+asm_peb+pkg_peb)*(1+freight_duty)*(1+B$30)+dtc_ship+$A36*(1-dtc_disc)*(pay_pct+warranty_pct)+pay_fixed)/($A36*(1-dtc_disc)*(1-returns_pct)) -> 0.54932412 | C36: =1-((bom_peb+asm_peb+pkg_peb)*(1+freight_duty)*(1+C$30)+dtc_ship+$A36*(1-dtc_disc)*(pay_pct+warranty_pct)+pay_fixed)/($A36*(1-dtc_disc)*(1-returns_pct)) -> 0.52993129 | D36: =1-((bom_peb+asm_peb+pkg_peb)*(1+freight_duty)*(1+D$30)+dtc_ship+$A36*(1-dtc_disc)*(pay_pct+warranty_pct)+pay_fixed)/($A36*(1-dtc_disc)*(1-returns_pct)) -> 0.51053847 | E36: =1-((bom_peb+asm_peb+pkg_peb)*(1+freight_duty)*(1+E$30)+dtc_ship+$A36*(1-dtc_disc)*(pay_pct+warranty_pct)+pay_fixed)/($A36*(1-dtc_disc)*(1-returns_pct)) -> 0.49114565 | F36: =1-((bom_peb+asm_peb+pkg_peb)*(1+freight_duty)*(1+F$30)+dtc_ship+$A36*(1-dtc_disc)*(pay_pct+warranty_pct)+pay_fixed)/($A36*(1-dtc_disc)*(1-returns_pct)) -> 0.47175282 | G36: =1-((bom_peb+asm_peb+pkg_peb)*(1+freight_duty)*(1+G$30)+dtc_ship+$A36*(1-dtc_disc)*(pay_pct+warranty_pct)+pay_fixed)/($A36*(1-dtc_disc)*(1-returns_pct)) -> 0.45236 | H36: =1-((bom_peb+asm_peb+pkg_peb)*(1+freight_duty)*(1+H$30)+dtc_ship+$A36*(1-dtc_disc)*(pay_pct+warranty_pct)+pay_fixed)/($A36*(1-dtc_disc)*(1-returns_pct)) -> 0.41357435
A38: Square: price \ COGS delta | B38: -0.15 | C38: -0.1 | D38: -0.05 | E38: 0 | F38: 0.05 | G38: 0.1 | H38: 0.2
A39: 249 | B39: =1-((bom_sq+asm_sq+pkg_sq)*(1+freight_duty)*(1+B$38)+dtc_ship+$A39*(1-dtc_disc)*(pay_pct+warranty_pct)+pay_fixed)/($A39*(1-dtc_disc)*(1-returns_pct)) -> 0.039357007 | C39: =1-((bom_sq+asm_sq+pkg_sq)*(1+freight_duty)*(1+C$38)+dtc_ship+$A39*(1-dtc_disc)*(pay_pct+warranty_pct)+pay_fixed)/($A39*(1-dtc_disc)*(1-returns_pct)) -> -0.011190729 | D39: =1-((bom_sq+asm_sq+pkg_sq)*(1+freight_duty)*(1+D$38)+dtc_ship+$A39*(1-dtc_disc)*(pay_pct+warranty_pct)+pay_fixed)/($A39*(1-dtc_disc)*(1-returns_pct)) -> -0.061738465 | E39: =1-((bom_sq+asm_sq+pkg_sq)*(1+freight_duty)*(1+E$38)+dtc_ship+$A39*(1-dtc_disc)*(pay_pct+warranty_pct)+pay_fixed)/($A39*(1-dtc_disc)*(1-returns_pct)) -> -0.1122862 | F39: =1-((bom_sq+asm_sq+pkg_sq)*(1+freight_duty)*(1+F$38)+dtc_ship+$A39*(1-dtc_disc)*(pay_pct+warranty_pct)+pay_fixed)/($A39*(1-dtc_disc)*(1-returns_pct)) -> -0.16283394 | G39: =1-((bom_sq+asm_sq+pkg_sq)*(1+freight_duty)*(1+G$38)+dtc_ship+$A39*(1-dtc_disc)*(pay_pct+warranty_pct)+pay_fixed)/($A39*(1-dtc_disc)*(1-returns_pct)) -> -0.21338167 | H39: =1-((bom_sq+asm_sq+pkg_sq)*(1+freight_duty)*(1+H$38)+dtc_ship+$A39*(1-dtc_disc)*(pay_pct+warranty_pct)+pay_fixed)/($A39*(1-dtc_disc)*(1-returns_pct)) -> -0.31447715
A40: 269 | B40: =1-((bom_sq+asm_sq+pkg_sq)*(1+freight_duty)*(1+B$38)+dtc_ship+$A40*(1-dtc_disc)*(pay_pct+warranty_pct)+pay_fixed)/($A40*(1-dtc_disc)*(1-returns_pct)) -> 0.10698536 | C40: =1-((bom_sq+asm_sq+pkg_sq)*(1+freight_duty)*(1+C$38)+dtc_ship+$A40*(1-dtc_disc)*(pay_pct+warranty_pct)+pay_fixed)/($A40*(1-dtc_disc)*(1-returns_pct)) -> 0.060195818 | D40: =1-((bom_sq+asm_sq+pkg_sq)*(1+freight_duty)*(1+D$38)+dtc_ship+$A40*(1-dtc_disc)*(pay_pct+warranty_pct)+pay_fixed)/($A40*(1-dtc_disc)*(1-returns_pct)) -> 0.013406278 | E40: =1-((bom_sq+asm_sq+pkg_sq)*(1+freight_duty)*(1+E$38)+dtc_ship+$A40*(1-dtc_disc)*(pay_pct+warranty_pct)+pay_fixed)/($A40*(1-dtc_disc)*(1-returns_pct)) -> -0.033383262 | F40: =1-((bom_sq+asm_sq+pkg_sq)*(1+freight_duty)*(1+F$38)+dtc_ship+$A40*(1-dtc_disc)*(pay_pct+warranty_pct)+pay_fixed)/($A40*(1-dtc_disc)*(1-returns_pct)) -> -0.080172802 | G40: =1-((bom_sq+asm_sq+pkg_sq)*(1+freight_duty)*(1+G$38)+dtc_ship+$A40*(1-dtc_disc)*(pay_pct+warranty_pct)+pay_fixed)/($A40*(1-dtc_disc)*(1-returns_pct)) -> -0.12696234 | H40: =1-((bom_sq+asm_sq+pkg_sq)*(1+freight_duty)*(1+H$38)+dtc_ship+$A40*(1-dtc_disc)*(pay_pct+warranty_pct)+pay_fixed)/($A40*(1-dtc_disc)*(1-returns_pct)) -> -0.22054142
A41: 279 | B41: =1-((bom_sq+asm_sq+pkg_sq)*(1+freight_duty)*(1+B$38)+dtc_ship+$A41*(1-dtc_disc)*(pay_pct+warranty_pct)+pay_fixed)/($A41*(1-dtc_disc)*(1-returns_pct)) -> 0.1371636 | C41: =1-((bom_sq+asm_sq+pkg_sq)*(1+freight_duty)*(1+C$38)+dtc_ship+$A41*(1-dtc_disc)*(pay_pct+warranty_pct)+pay_fixed)/($A41*(1-dtc_disc)*(1-returns_pct)) -> 0.092051105 | D41: =1-((bom_sq+asm_sq+pkg_sq)*(1+freight_duty)*(1+D$38)+dtc_ship+$A41*(1-dtc_disc)*(pay_pct+warranty_pct)+pay_fixed)/($A41*(1-dtc_disc)*(1-returns_pct)) -> 0.04693861 | E41: =1-((bom_sq+asm_sq+pkg_sq)*(1+freight_duty)*(1+E$38)+dtc_ship+$A41*(1-dtc_disc)*(pay_pct+warranty_pct)+pay_fixed)/($A41*(1-dtc_disc)*(1-returns_pct)) -> 0.001826114 | F41: =1-((bom_sq+asm_sq+pkg_sq)*(1+freight_duty)*(1+F$38)+dtc_ship+$A41*(1-dtc_disc)*(pay_pct+warranty_pct)+pay_fixed)/($A41*(1-dtc_disc)*(1-returns_pct)) -> -0.043286382 | G41: =1-((bom_sq+asm_sq+pkg_sq)*(1+freight_duty)*(1+G$38)+dtc_ship+$A41*(1-dtc_disc)*(pay_pct+warranty_pct)+pay_fixed)/($A41*(1-dtc_disc)*(1-returns_pct)) -> -0.088398877 | H41: =1-((bom_sq+asm_sq+pkg_sq)*(1+freight_duty)*(1+H$38)+dtc_ship+$A41*(1-dtc_disc)*(pay_pct+warranty_pct)+pay_fixed)/($A41*(1-dtc_disc)*(1-returns_pct)) -> -0.17862387
